Workbook

Sheet Vergleich
A1: Vergleich manuelle Messung (Waage) vs. Flowsensor (Plateau-Mittelwerte)
A2: Manuell: MW/min [ml] aus Tabelle1 Zeile 10 (Formel unverändert übernommen), umgerechnet ×1000 in µl/min. Sensor: Plateau-MW aus Blatt "Plateaus".
A4: Kanal | B4: Datei | C4: Soll-Flussrate [µl/min] | D4: Manuell MW/min [ml/min] | E4: Manuell [µl/min] | F4: Sensor Plateau-MW [µl/min] | G4: Sensor Std-Abw. [µl/min] | H4: Abweichung Sensor − Manuell [µl/min] | I4: Rel. Abweichung [%] | J4: Faktor Manuell/Sensor
A5: Channel 1 | B5: #027 | C5: =Tabelle1!K2 -> 250 | D5: =Tabelle1!K10 -> 0.243268 | E5: =D5*1000 -> 243.268 | F5: =Plateaus!G2 -> 229.83281 | G5: =Plateaus!H2 -> 6.975373 | H5: =F5-E5 -> -13.435191 | I5: =IF(E5=0,"",H5/E5) -> -0.055227943 | J5: =IF(F5=0,"",E5/F5) -> 1.0584564
A6: Channel 1 | B6: #027 | C6: =Tabelle1!L2 -> 500 | D6: =Tabelle1!L10 -> 0.482548 | E6: =D6*1000 -> 482.548 | F6: =Plateaus!G3 -> 445.73105 | G6: =Plateaus!H3 -> 14.155344 | H6: =F6-E6 -> -36.816951 | I6: =IF(E6=0,"",H6/E6) -> -0.076296972 | J6: =IF(F6=0,"",E6/F6) -> 1.082599
A7: Channel 1 | B7: #027 | C7: =Tabelle1!M2 -> 750 | D7: =Tabelle1!M10 -> 0.71784 | E7: =D7*1000 -> 717.84 | F7: =Plateaus!G4 -> 645.34042 | G7: =Plateaus!H4 -> 16.984742 | H7: =F7-E7 -> -72.499577 | I7: =IF(E7=0,"",H7/E7) -> -0.10099685 | J7: =IF(F7=0,"",E7/F7) -> 1.1123432
A8: Channel 1 | B8: #027 | C8: =Tabelle1!N2 -> 1000 | D8: =Tabelle1!N10 -> 0.97706 | E8: =D8*1000 -> 977.06 | F8: =Plateaus!G5 -> 839.30181 | G8: =Plateaus!H5 -> 19.663426 | H8: =F8-E8 -> -137.75819 | I8: =IF(E8=0,"",H8/E8) -> -0.14099256 | J8: =IF(F8=0,"",E8/F8) -> 1.1641343
A9: Channel 1 | B9: #027 | C9: =Tabelle1!O2 -> 2000 | D9: =Tabelle1!O10 -> 1.992006 | E9: =D9*1000 -> 1992.006 | F9: =Plateaus!G6 -> 1048.4314 | G9: =Plateaus!H6 -> 109.99603 | H9: =F9-E9 -> -943.57462 | I9: =IF(E9=0,"",H9/E9) -> -0.47368061 | J9: =IF(F9=0,"",E9/F9) -> 1.899987
A10: Channel 2 | B10: #028 | C10: =Tabelle1!S2 -> 250 | D10: =Tabelle1!S10 -> 0.2330986 | E10: =D10*1000 -> 233.0986 | F10: =Plateaus!G7 -> 250.29328 | G10: =Plateaus!H7 -> 9.6263345 | H10: =F10-E10 -> 17.194681 | I10: =IF(E10=0,"",H10/E10) -> 0.073765697 | J10: =IF(F10=0,"",E10/F10) -> 0.93130187
A11: Channel 2 | B11: #028 | C11: =Tabelle1!T2 -> 500 | D11: =Tabelle1!T10 -> 0.4843426 | E11: =D11*1000 -> 484.3426 | F11: =Plateaus!G8 -> 494.60833 | G11: =Plateaus!H8 -> 9.4232775 | H11: =F11-E11 -> 10.265733 | I11: =IF(E11=0,"",H11/E11) -> 0.02119519 | J11: =IF(F11=0,"",E11/F11) -> 0.97924472
A12: Channel 2 | B12: #028 | C12: =Tabelle1!U2 -> 750 | D12: =Tabelle1!U10 -> 0.7371818 | E12: =D12*1000 -> 737.1818 | F12: =Plateaus!G9 -> 756.49376 | G12: =Plateaus!H9 -> 15.800718 | H12: =F12-E12 -> 19.311964 | I12: =IF(E12=0,"",H12/E12) -> 0.026197017 | J12: =IF(F12=0,"",E12/F12) -> 0.97447175
A13: Channel 2 | B13: #028 | C13: =Tabelle1!V2 -> 1000 | D13: =Tabelle1!V10 -> 0.989024 | E13: =D13*1000 -> 989.024 | F13: =Plateaus!G10 -> 1009.4097 | G13: =Plateaus!H10 -> 18.039691 | H13: =F13-E13 -> 20.385692 | I13: =IF(E13=0,"",H13/E13) -> 0.020611928 | J13: =IF(F13=0,"",E13/F13) -> 0.97980434
A14: Channel 2 | B14: #028 | C14: =Tabelle1!W2 -> 1500 | D14: =Tabelle1!W10 -> 1.507464 | E14: =D14*1000 -> 1507.464 | F14: =Plateaus!G11 -> 1533.7541 | G14: =Plateaus!H11 -> 34.09607 | H14: =F14-E14 -> 26.29007 | I14: =IF(E14=0,"",H14/E14) -> 0.017439933 | J14: =IF(F14=0,"",E14/F14) -> 0.98285901
A15: Channel 3 | B15: #029 | C15: =Tabelle1!AA2 -> 250 | D15: =Tabelle1!AA10 -> 0.236289 | E15: =D15*1000 -> 236.289 | F15: =Plateaus!G12 -> 238.19771 | G15: =Plateaus!H12 -> 24.918815 | H15: =F15-E15 -> 1.908712 | I15: =IF(E15=0,"",H15/E15) -> 0.0080778709 | J15: =IF(F15=0,"",E15/F15) -> 0.99198686
A16: Channel 3 | B16: #029 | C16: =Tabelle1!AB2 -> 500 | D16: =Tabelle1!AB10 -> 0.4913216 | E16: =D16*1000 -> 491.3216 | F16: =Plateaus!G13 -> 467.42224 | G16: =Plateaus!H13 -> 14.51454 | H16: =F16-E16 -> -23.899365 | I16: =IF(E16=0,"",H16/E16) -> -0.048643017 | J16: =IF(F16=0,"",E16/F16) -> 1.0511301
A17: Channel 3 | B17: #029 | C17: =Tabelle1!AC2 -> 750 | D17: =Tabelle1!AC10 -> 0.739774 | E17: =D17*1000 -> 739.774 | F17: =Plateaus!G14 -> 687.33212 | G17: =Plateaus!H14 -> 16.96664 | H17: =F17-E17 -> -52.441875 | I17: =IF(E17=0,"",H17/E17) -> -0.070889049 | J17: =IF(F17=0,"",E17/F17) -> 1.0762977
A18: Channel 3 | B18: #029 | C18: =Tabelle1!AD2 -> 1000 | D18: =Tabelle1!AD10 -> 0.991018 | E18: =D18*1000 -> 991.018 | F18: =Plateaus!G15 -> 902.32686 | G18: =Plateaus!H15 -> 21.902354 | H18: =F18-E18 -> -88.691145 | I18: =IF(E18=0,"",H18/E18) -> -0.089494989 | J18: =IF(F18=0,"",E18/F18) -> 1.0982916
A19: Channel 3 | B19: #029 | C19: =Tabelle1!AE2 -> 2000 | D19: =Tabelle1!AE10 -> 1.980042 | E19: =D19*1000 -> 1980.042 | F19: =Plateaus!G16 -> 1719.254 | G19: =Plateaus!H16 -> 37.772906 | H19: =F19-E19 -> -260.788 | I19: =IF(E19=0,"",H19/E19) -> -0.13170832 | J19: =IF(F19=0,"",E19/F19) -> 1.1516867
A20: Channel 4 | B20: #031 | C20: =Tabelle1!AI2 -> 250 | D20: =Tabelle1!AI10 -> 0.23928 | E20: =D20*1000 -> 239.28 | F20: =Plateaus!G17 -> 225.83099 | G20: =Plateaus!H17 -> 22.152481 | H20: =F20-E20 -> -13.449008 | I20: =IF(E20=0,"",H20/E20) -> -0.056206152 | J20: =IF(F20=0,"",E20/F20) -> 1.0595534
A21: Channel 4 | B21: #031 | C21: =Tabelle1!AJ2 -> 500 | D21: =Tabelle1!AJ10 -> 0.48853 | E21: =D21*1000 -> 488.53 | F21: =Plateaus!G18 -> 418.24487 | G21: =Plateaus!H18 -> 14.027229 | H21: =F21-E21 -> -70.285128 | I21: =IF(E21=0,"",H21/E21) -> -0.14387065 | J21: =IF(F21=0,"",E21/F21) -> 1.1680478
A22: Channel 4 | B22: #031 | C22: =Tabelle1!AK2 -> 750 | D22: =Tabelle1!AK10 -> 0.741768 | E22: =D22*1000 -> 741.768 | F22: =Plateaus!G19 -> 598.13231 | G22: =Plateaus!H19 -> 11.733588 | H22: =F22-E22 -> -143.63569 | I22: =IF(E22=0,"",H22/E22) -> -0.19363964 | J22: =IF(F22=0,"",E22/F22) -> 1.2401403
A23: Channel 4 | B23: #031 | C23: =Tabelle1!AL2 -> 1000 | D23: =Tabelle1!AL10 -> 0.98703 | E23: =D23*1000 -> 987.03 | F23: =Plateaus!G20 -> 768.11305 | G23: =Plateaus!H20 -> 14.953769 | H23: =F23-E23 -> -218.91695 | I23: =IF(E23=0,"",H23/E23) -> -0.22179362 | J23: =IF(F23=0,"",E23/F23) -> 1.2850062
A24: Channel 4 | B24: #031 | C24: =Tabelle1!AM2 -> 2000 | D24: =Tabelle1!AM10 -> 1.992006 | E24: =D24*1000 -> 1992.006 | F24: =Plateaus!G21 -> 1346.0425 | G24: =Plateaus!H21 -> 23.883291 | H24: =F24-E24 -> -645.9635 | I24: =IF(E24=0,"",H24/E24) -> -0.32427789 | J24: =IF(F24=0,"",E24/F24) -> 1.4798983
A25: Channel 5 | B25: #032 | C25: =Tabelle1!AQ2 -> 250 | D25: =Tabelle1!AQ10 -> 0.241274 | E25: =D25*1000 -> 241.274 | F25: =Plateaus!G22 -> 247.30407 | G25: =Plateaus!H22 -> 11.775996 | H25: =F25-E25 -> 6.0300675 | I25: =IF(E25=0,"",H25/E25) -> 0.024992612 | J25: =IF(F25=0,"",E25/F25) -> 0.97561679
A26: Channel 5 | B26: #032 | C26: =Tabelle1!AR2 -> 500 | D26: =Tabelle1!AR10 -> 0.48853 | E26: =D26*1000 -> 488.53 | F26: =Plateaus!G23 -> 497.30732 | G26: =Plateaus!H23 -> 15.136324 | H26: =F26-E26 -> 8.7773242 | I26: =IF(E26=0,"",H26/E26) -> 0.017966807 | J26: =IF(F26=0,"",E26/F26) -> 0.9823503
A27: Channel 5 | B27: #032 | C27: =Tabelle1!AS2 -> 750 | D27: =Tabelle1!AS10 -> 0.735786 | E27: =D27*1000 -> 735.786 | F27: =Plateaus!G24 -> 747.27903 | G27: =Plateaus!H24 -> 19.184698 | H27: =F27-E27 -> 11.493029 | I27: =IF(E27=0,"",H27/E27) -> 0.01562007 | J27: =IF(F27=0,"",E27/F27) -> 0.98462016
A28: Channel 5 | B28: #032 | C28: =Tabelle1!AT2 -> 1000 | D28: =Tabelle1!AT10 -> 0.983042 | E28: =D28*1000 -> 983.042 | F28: =Plateaus!G25 -> 997.29294 | G28: =Plateaus!H25 -> 25.174969 | H28: =F28-E28 -> 14.250938 | I28: =IF(E28=0,"",H28/E28) -> 0.014496774 | J28: =IF(F28=0,"",E28/F28) -> 0.98571038
A29: Channel 5 | B29: #032 | C29: =Tabelle1!AU2 -> 2000 | D29: =Tabelle1!AU10 -> 1.990012 | E29: =D29*1000 -> 1990.012 | F29: =Plateaus!G26 -> 2031.3463 | G29: =Plateaus!H26 -> 50.617811 | H29: =F29-E29 -> 41.334306 | I29: =IF(E29=0,"",H29/E29) -> 0.020770883 | J29: =IF(F29=0,"",E29/F29) -> 0.97965177
A30: Channel 6 | B30: #034 | C30: =Tabelle1!AY2 -> 250 | D30: =Tabelle1!AY10 -> 0.241274 | E30: =D30*1000 -> 241.274 | F30: =Plateaus!G27 -> 242.13601 | G30: =Plateaus!H27 -> 8.0657447 | H30: =F30-E30 -> 0.8620119 | I30: =IF(E30=0,"",H30/E30) -> 0.0035727509 | J30: =IF(F30=0,"",E30/F30) -> 0.99643997
A31: Channel 6 | B31: #034 | C31: =Tabelle1!AZ2 -> 500 | D31: =Tabelle1!AZ10 -> 0.491521 | E31: =D31*1000 -> 491.521 | F31: =Plateaus!G28 -> 477.42542 | G31: =Plateaus!H28 -> 12.066367 | H31: =F31-E31 -> -14.095578 | I31: =IF(E31=0,"",H31/E31) -> -0.028677468 | J31: =IF(F31=0,"",E31/F31) -> 1.0295241
A32: Channel 6 | B32: #034 | C32: =Tabelle1!BA2 -> 750 | D32: =Tabelle1!BA10 -> 0.735786 | E32: =D32*1000 -> 735.786 | F32: =Plateaus!G29 -> 712.82198 | G32: =Plateaus!H29 -> 17.539226 | H32: =F32-E32 -> -22.96402 | I32: =IF(E32=0,"",H32/E32) -> -0.031210188 | J32: =IF(F32=0,"",E32/F32) -> 1.0322156
A33: Channel 6 | B33: #034 | C33: =Tabelle1!BB2 -> 1000 | D33: =Tabelle1!BB10 -> 0.989024 | E33: =D33*1000 -> 989.024 | F33: =Plateaus!G30 -> 939.07387 | G33: =Plateaus!H30 -> 21.790548 | H33: =F33-E33 -> -49.95013 | I33: =IF(E33=0,"",H33/E33) -> -0.050504467 | J33: =IF(F33=0,"",E33/F33) -> 1.0531908
A34: Channel 6 | B34: #034 | C34: =Tabelle1!BC2 -> 2000 | D34: =Tabelle1!BC10 -> 1.980042 | E34: =D34*1000 -> 1980.042 | F34: =Plateaus!G31 -> 1833.6012 | G34: =Plateaus!H31 -> 41.069827 | H34: =F34-E34 -> -146.4408 | I34: =IF(E34=0,"",H34/E34) -> -0.07395843 | J34: =IF(F34=0,"",E34/F34) -> 1.0798651
A35: Channel 7 | B35: #035 | C35: =Tabelle1!BG2 -> 250 | D35: =Tabelle1!BG10 -> 0.22931 | E35: =D35*1000 -> 229.31 | F35: =Plateaus!G32 -> 260.26384 | G35: =Plateaus!H32 -> 9.0062837 | H35: =F35-E35 -> 30.953842 | I35: =IF(E35=0,"",H35/E35) -> 0.13498688 | J35: =IF(F35=0,"",E35/F35) -> 0.88106745
A36: Channel 7 | B36: #035 | C36: =Tabelle1!BH2 -> 500 | D36: =Tabelle1!BH10 -> 0.486536 | E36: =D36*1000 -> 486.536 | F36: =Plateaus!G33 -> 523.97041 | G36: =Plateaus!H33 -> 16.337084 | H36: =F36-E36 -> 37.434409 | I36: =IF(E36=0,"",H36/E36) -> 0.076940677 | J36: =IF(F36=0,"",E36/F36) -> 0.92855625
A37: Channel 7 | B37: #035 | C37: =Tabelle1!BI2 -> 750 | D37: =Tabelle1!BI10 -> 0.731798 | E37: =D37*1000 -> 731.798 | F37: =Plateaus!G34 -> 802.15599 | G37: =Plateaus!H34 -> 20.621772 | H37: =F37-E37 -> 70.357988 | I37: =IF(E37=0,"",H37/E37) -> 0.096144002 | J37: =IF(F37=0,"",E37/F37) -> 0.91228889
A38: Channel 7 | B38: #035 | C38: =Tabelle1!BJ2 -> 1000 | D38: =Tabelle1!BJ10 -> 0.983042 | E38: =D38*1000 -> 983.042 | F38: =Plateaus!G35 -> 1129.591 | G38: =Plateaus!H35 -> 30.960675 | H38: =F38-E38 -> 146.54895 | I38: =IF(E38=0,"",H38/E38) -> 0.149077 | J38: =IF(F38=0,"",E38/F38) -> 0.8702637
A39: Channel 7 | B39: #035 | C39: =Tabelle1!BK2 -> 2000 | D39: =Tabelle1!BK10 -> 1.98403 | E39: =D39*1000 -> 1984.03 | F39: =Plateaus!G36 -> 2269.3149 | G39: =Plateaus!H36 -> 67.931445 | H39: =F39-E39 -> 285.28485 | I39: =IF(E39=0,"",H39/E39) -> 0.14379059 | J39: =IF(F39=0,"",E39/F39) -> 0.87428591
A41: Mittlere rel. Abweichung je Kanal
A42: Kanal | B42: Datei | C42: Ø rel. Abw. [%] | D42: Ø Faktor Manuell/Sensor
...

Sheet Boxplot manuell
A1: Manuelle Messung: Abweichung der Kanäle vom Mittel aller Kanäle je Flussrate
A2: MW/min je Kanal (µl/min, wie Tabelle1 Z.10 ×1000) und Abweichung vom kanalübergreifenden Mittel. Ch2 1500 µl/min ausgeschlossen; AY4 als 0,22 gewertet.
A4: Kanal | B4: 250 µl/min MW/min | C4: 500 µl/min MW/min | D4: 750 µl/min MW/min | E4: 1000 µl/min MW/min | F4: 2000 µl/min MW/min | G4: 250 µl/min Abw. [%] | H4: 500 µl/min Abw. [%] | I4: 750 µl/min Abw. [%] | J4: 1000 µl/min Abw. [%] | K4: 2000 µl/min Abw. [%]
A5: Channel 1 | B5: 243.27 | C5: 482.55 | D5: 717.84 | E5: 977.06 | F5: 1992.01 | G5: 0.023489933 | H5: -0.010398411 | I5: -0.022384296 | J5: -0.0086705202 | K5: 0.0028442362
A6: Channel 2 | B6: 233.1 | C6: 484.34 | D6: 737.18 | E6: 989.02 | G6: -0.019295302 | H6: -0.0067180745 | I6: 0.0039570159 | J6: 0.0034682081
A7: Channel 3 | B7: 236.29 | C7: 491.32 | D7: 739.77 | E7: 991.02 | F7: 1980.04 | G7: -0.0058724832 | H7: 0.0075943451 | I7: 0.0074872949 | J7: 0.0054913295 | K7: -0.0031788523
A8: Channel 4 | B8: 239.28 | C8: 488.53 | D8: 741.77 | E8: 987.03 | F8: 1992.01 | G8: 0.0067114094 | H8: 0.0018693773 | I8: 0.010202894 | J8: 0.0014450867 | K8: 0.0028442362
A9: Channel 5 | B9: 241.27 | C9: 488.53 | D9: 735.79 | E9: 983.04 | F9: 1990.01 | G9: 0.015100671 | H9: 0.0018693773 | I9: 0.0020560965 | J9: -0.0026011561 | K9: 0.0018403882
A10: Channel 6 | B10: 241.27 | C10: 491.52 | D10: 735.79 | E10: 989.02 | F10: 1980.04 | G10: 0.015100671 | H10: 0.0080032714 | I10: 0.0020560965 | J10: 0.0034682081 | K10: -0.0031788523
A11: Channel 7 | B11: 229.31 | C11: 486.54 | D11: 731.8 | E11: 983.04 | F11: 1984.03 | G11: -0.035234899 | H11: -0.0022198855 | I11: -0.0033751018 | J11: -0.0026011561 | K11: -0.0011711561
A12: Mittel | B12: =AVERAGE(B5:B11) -> 237.68429 | C12: =AVERAGE(C5:C11) -> 487.61857 | D12: =AVERAGE(D5:D11) -> 734.27714 | E12: =AVERAGE(E5:E11) -> 985.60429 | F12: =AVERAGE(F5:F11) -> 1986.3567
A13: VK (Std/MW) | B13: =STDEV(B5:B11)/B12 -> 0.021214334 | C13: =STDEV(C5:C11)/C12 -> 0.0069133951 | D13: =STDEV(D5:D11)/D12 -> 0.010775738 | E13: =STDEV(E5:E11)/E12 -> 0.0049159164 | F13: =STDEV(F5:F11)/F12 -> 0.0028698502

Sheet Boxplot
A1: Boxplot: rel. Abweichung Sensor vs. manuell je Kanal (Daten aus Blatt "Vergleich", Spalte I)

Sheet Tabelle1
A1: Channel: 0 | B1: V-Flow [ul/min] | I1: Channel: 1 | J1: V-Flow [ul/min] | Q1: Channel: 2 | R1: V-Flow [ul/min] | Y1: Channel: 3 | Z1: V-Flow [ul/min] | AG1: Channel: 4 | AH1: V-Flow [ul/min] | AO1: Channel: 5 | AP1: V-Flow [ul/min] | AW1: Channel: 6 | AX1: V-Flow [ul/min] | BE1: Channel: 7 | BF1: V-Flow [ul/min]
A2: Zeit [min] | B2: 0 | C2: 250 | D2: 500 | E2: 750 | F2: 1000 | G2: 2000 | I2: Zeit [min] | J2: 0 | K2: 250 | L2: 500 | M2: 750 | N2: 1000 | O2: 2000 | Q2: Zeit [min] | R2: 0 | S2: 250 | T2: 500 | U2: 750 | V2: 1000 | W2: 1500 | Y2: Zeit [min] | Z2: 0 | AA2: 250 | AB2: 500 | AC2: 750 | AD2: 1000 | AE2: 2000 | AG2: Zeit [min] | AH2: 0 | AI2: 250 | AJ2: 500 | AK2: 750 | AL2: 1000 | AM2: 2000 | AO2: Zeit [min] | AP2: 0 | AQ2: 250 | AR2: 500 | AS2: 750 | AT2: 1000 | AU2: 2000 | AW2: Zeit [min] | AX2: 0 | AY2: 250 | AZ2: 500 | BA2: 750 | BB2: 1000 | BC2: 2000 | BE2: Zeit [min] | BF2: 0 | BG2: 250 | BH2: 500 | BI2: 750 | BJ2: 1000 | BK2: 2000
A3: 0 | I3: 0 | J3: 0 | K3: 0.02 | L3: 1.24 | M3: 3.7 | N3: 7.4 | O3: 12.36 | Q3: 0 | R3: 0 | S3: 0 | T3: 1.181 | U3: 3.633 | V3: 7.36 | W3: 12.38 | Y3: 0 | Z3: 0 | AA3: 0 | AB3: 1.196 | AC3: 3.67 | AD3: 7.4 | AE3: 12.37 | AG3: 0 | AH3: 0 | AI3: 0 | AJ3: 1.21 | AK3: 3.68 | AL3: 7.42 | AM3: 12.39 | AO3: 0 | AP3: 0 | AQ3: 0 | AR3: 1.22 | AS3: 3.7 | AT3: 7.41 | AU3: 0 | AW3: 0 | AX3: 0 | AY3: 0 | AZ3: 1.22 | BA3: 3.71 | BB3: 7.43 | BC3: 12.42 | BE3: 0 | BF3: 0 | BG3: 0 | BH3: 1.16 | BI3: 3.62 | BJ3: 7.33 | BK3: 12.29
A4: 1 | I4: 1 | J4: 0 | K4: 0.2 | L4: 1.74 | M4: 4.3 | N4: 8.2 | O4: 14.5 | Q4: 1 | R4: 0 | S4: 0.189 | T4: 1.65 | U4: 4.33 | V4: 8.3 | W4: 13.83 | Y4: 1 | Z4: 0 | AA4: 0.21 | AB4: 1.7 | AC4: 4.4 | AD4: 8.37 | AE4: 14.3 | AG4: 1 | AH4: 0 | AI4: 0.21 | AJ4: 1.69 | AK4: 4.4 | AL4: 8.38 | AM4: 14.38 | AO4: 1 | AP4: 0 | AQ4: 0.21 | AR4: 1.69 | AS4: 4.4 | AT4: 8.35 | AU4: 1.98 | AW4: 1 | AX4: 0 | AY4: 2.2 | AZ4: 1.69 | BA4: 4.4 | BB4: 8.3 | BC4: 14.37 | BE4: 1 | BF4: 0 | BG4: 0.17 | BH4: 1.64 | BI4: 4.32 | BJ4: 8.28 | BK4: 14.24
A5: 2 | I5: 2 | J5: 0 | K5: 0.42 | L5: 2.23 | M5: 5 | N5: 9.3 | O5: 16.42 | Q5: 2 | R5: 0 | S5: 0.435 | T5: 2.14 | U5: 5.07 | V5: 9.3 | W5: 15.35 | Y5: 2 | Z5: 0 | AA5: 0.445 | AB5: 2.18 | AC5: 5.14 | AD5: 9.37 | AE5: 16.3 | AG5: 2 | AH5: 0 | AI5: 0.46 | AJ5: 2.185 | AK5: 5.15 | AL5: 9.38 | AM5: 16.39 | AO5: 2 | AP5: 0 | AQ5: 0.451 | AR5: 2.183 | AS5: 5.14 | AT5: 9.35 | AU5: 3.98 | AW5: 2 | AX5: 0 | AY5: 0.47 | AZ5: 2.19 | BA5: 5.12 | BB5: 9.4 | BC5: 16.36 | BE5: 2 | BF5: 0 | BG5: 0.42 | BH5: 2.13 | BI5: 5.07 | BJ5: 9.28 | BK5: 16.25
A6: 3 | I6: 3 | J6: 0.018 | K6: 0.6 | L6: 2.7 | M6: 5.8 | N6: 10.3 | O6: 18.45 | Q6: 3 | R6: 0 | S6: 0.675 | T6: 2.63 | U6: 5.82 | V6: 10.31 | W6: 16.88 | Y6: 3 | Z6: 0 | AA6: 0.69 | AB6: 2.67 | AC6: 5.88 | AD6: 10.38 | AE6: 18.3 | AG6: 3 | AH6: 0 | AI6: 0.707 | AJ6: 2.68 | AK6: 5.89 | AL6: 10.38 | AM6: 18.38 | AO6: 3 | AP6: 0 | AQ6: 0.7 | AR6: 2.68 | AS6: 5.88 | AT6: 10.35 | AU6: 5.98 | AW6: 3 | AX6: 0 | AY6: 0.72 | AZ6: 2.69 | BA6: 5.9 | BB6: 10.4 | BC6: 18.36 | BE6: 3 | BF6: 0 | BG6: 0.67 | BH6: 2.62 | BI6: 5.8 | BJ6: 10.28 | BK6: 18.24
A7: 4 | I7: 4 | J7: 0.018 | K7: 0.84 | L7: 3.2 | M7: 6.3 | N7: 11.27 | O7: 20.45 | Q7: 4 | R7: 0 | S7: 0.935 | T7: 3.12 | U7: 6.55 | V7: 11.32 | W7: 18.41 | Y7: 4 | Z7: 0 | AA7: 0.94 | AB7: 3.17 | AC7: 6.62 | AD7: 11.36 | AE7: 20.3 | AG7: 4 | AH7: 0 | AI7: 0.957 | AJ7: 3.169 | AK7: 6.64 | AL7: 11.37 | AM7: 20.37 | AO7: 4 | AP7: 0 | AQ7: 0.95 | AR7: 3.17 | AS7: 6.63 | AT7: 11.34 | AU7: 7.98 | AW7: 4 | AX7: 0 | AY7: 0.98 | AZ7: 3.19 | BA7: 6.7 | BB7: 11.4 | BC7: 20.37 | BE7: 4 | BF7: 0 | BG7: 0.91 | BH7: 3.1 | BI7: 6.54 | BJ7: 11.28 | BK7: 20.25
A8: 5 | I8: 5 | J8: 0.02 | K8: 1.24 | L8: 3.66 | M8: 7.3 | N8: 12.3 | O8: 22.35 | Q8: 5 | R8: 0 | S8: 1.169 | T8: 3.61 | U8: 7.33 | V8: 12.32 | W8: 19.94 | Y8: 5 | Z8: 0 | AA8: 1.185 | AB8: 3.66 | AC8: 7.38 | AD8: 12.37 | AE8: 22.3 | AG8: 5 | AH8: 0 | AI8: 1.2 | AJ8: 3.66 | AK8: 7.4 | AL8: 12.37 | AM8: 22.38 | AO8: 5 | AP8: 0 | AQ8: 1.21 | AR8: 3.67 | AS8: 7.39 | AT8: 12.34 | AU8: 9.98 | AW8: 5 | AX8: 0 | AY8: 1.21 | AZ8: 3.685 | BA8: 7.4 | BB8: 12.39 | BC8: 22.35 | BE8: 5 | BF8: 0 | BG8: 1.15 | BH8: 3.6 | BI8: 7.29 | BJ8: 12.26 | BK8: 22.24
A9: ΜW/min | B9: =AVERAGE(B3-0,B4-B3,B5-B4,B6-B5,B7-B6,B8-B7) -> 0 | C9: =AVERAGE(C4-C3,C5-C4,C6-C5,C7-C6,C8-C7) -> 0 | D9: =AVERAGE(D4-D3,D5-D4,D6-D5,D7-D6,D8-D7) -> 0 | E9: =AVERAGE(E4-E3,E5-E4,E6-E5,E7-E6,E8-E7) -> 0 | F9: =AVERAGE(F4-F3,F5-F4,F6-F5,F7-F6,F8-F7) -> 0 | G9: =AVERAGE(G4-G3,G5-G4,G6-G5,G7-G6,G8-G7) -> 0 | H9: [g] | I9: ΜW/min | J9: =AVERAGE(J3-0,J4-J3,J5-J4,J6-J5,J7-J6,J8-J7) -> 0.0033333333 | K9: =AVERAGE(K4-K3,K5-K4,K6-K5,K7-K6,K8-K7) -> 0.244 | L9: =AVERAGE(L4-L3,L5-L4,L6-L5,L7-L6,L8-L7) -> 0.484 | M9: =AVERAGE(M4-M3,M5-M4,M6-M5,M7-M6,M8-M7) -> 0.72 | N9: =AVERAGE(N4-N3,N5-N4,N6-N5,N7-N6,N8-N7) -> 0.98 | O9: =AVERAGE(O4-O3,O5-O4,O6-O5,O7-O6,O8-O7) -> 1.998 | P9: [g] | Q9: ΜW/min | R9: =AVERAGE(R4-R3,R5-R4,R6-R5,R7-R6,R8-R7) -> 0 | S9: =AVERAGE(S4-S3,S5-S4,S6-S5,S7-S6,S8-S7) -> 0.2338 | T9: =AVERAGE(T4-T3,T5-T4,T6-T5,T7-T6,T8-T7) -> 0.4858 | U9: =AVERAGE(U4-U3,U5-U4,U6-U5,U7-U6,U8-U7) -> 0.7394 | V9: =AVERAGE(V4-V3,V5-V4,V6-V5,V7-V6,V8-V7) -> 0.992 | W9: =AVERAGE(W4-W3,W5-W4,W6-W5,W7-W6,W8-W7) -> 1.512 | X9: [g] | Y9: ΜW/min | Z9: =AVERAGE(Z4-Z3,Z5-Z4,Z6-Z5,Z7-Z6,Z8-Z7) -> 0 | AA9: =AVERAGE(AA4-AA3,AA5-AA4,AA6-AA5,AA7-AA6,AA8-AA7) -> 0.237 | AB9: =AVERAGE(AB4-AB3,AB5-AB4,AB6-AB5,AB7-AB6,AB8-AB7) -> 0.4928 | AC9: =AVERAGE(AC4-AC3,AC5-AC4,AC6-AC5,AC7-AC6,AC8-AC7) -> 0.742 | AD9: =AVERAGE(AD4-AD3,AD5-AD4,AD6-AD5,AD7-AD6,AD8-AD7) -> 0.994 | AE9: =AVERAGE(AE4-AE3,AE5-AE4,AE6-AE5,AE7-AE6,AE8-AE7) -> 1.986 | AF9: [g] | AG9: ΜW/min | AH9: =AVERAGE(AH4-AH3,AH5-AH4,AH6-AH5,AH7-AH6,AH8-AH7) -> 0 | AI9: =AVERAGE(AI4-AI3,AI5-AI4,AI6-AI5,AI7-AI6,AI8-AI7) -> 0.24 | AJ9: =AVERAGE(AJ4-AJ3,AJ5-AJ4,AJ6-AJ5,AJ7-AJ6,AJ8-AJ7) -> 0.49 | AK9: =AVERAGE(AK4-AK3,AK5-AK4,AK6-AK5,AK7-AK6,AK8-AK7) -> 0.744 | AL9: =AVERAGE(AL4-AL3,AL5-AL4,AL6-AL5,AL7-AL6,AL8-AL7) -> 0.99 | AM9: =AVERAGE(AM4-AM3,AM5-AM4,AM6-AM5,AM7-AM6,AM8-AM7) -> 1.998 | AN9: [g] | AO9: ΜW/min | AP9: =AVERAGE(AP4-AP3,AP5-AP4,AP6-AP5,AP7-AP6,AP8-AP7) -> 0 | AQ9: =AVERAGE(AQ4-AQ3,AQ5-AQ4,AQ6-AQ5,AQ7-AQ6,AQ8-AQ7) -> 0.242 | AR9: =AVERAGE(AR4-AR3,AR5-AR4,AR6-AR5,AR7-AR6,AR8-AR7) -> 0.49 | AS9: =AVERAGE(AS4-AS3,AS5-AS4,AS6-AS5,AS7-AS6,AS8-AS7) -> 0.738 | AT9: =AVERAGE(AT4-AT3,AT5-AT4,AT6-AT5,AT7-AT6,AT8-AT7) -> 0.986 | AU9: =AVERAGE(AU4-AU3,AU5-AU4,AU6-AU5,AU7-AU6,AU8-AU7) -> 1.996 | AV9: [g] | AW9: ΜW/min | AX9: =AVERAGE(AX4-AX3,AX5-AX4,AX6-AX5,AX7-AX6,AX8-AX7) -> 0 | AY9: =AVERAGE(AY4-AY3,AY5-AY4,AY6-AY5,AY7-AY6,AY8-AY7) -> 0.242 | AZ9: =AVERAGE(AZ4-AZ3,AZ5-AZ4,AZ6-AZ5,AZ7-AZ6,AZ8-AZ7) -> 0.493 | BA9: =AVERAGE(BA4-BA3,BA5-BA4,BA6-BA5,BA7-BA6,BA8-BA7) -> 0.738 | BB9: =AVERAGE(BB4-BB3,BB5-BB4,BB6-BB5,BB7-BB6,BB8-BB7) -> 0.992 | BC9: =AVERAGE(BC4-BC3,BC5-BC4,BC6-BC5,BC7-BC6,BC8-BC7) -> 1.986 | BD9: [g] | BE9: ΜW/min | BF9: =AVERAGE(BF4-BF3,BF5-BF4,BF6-BF5,BF7-BF6,BF8-BF7) -> 0 | BG9: =AVERAGE(BG4-BG3,BG5-BG4,BG6-BG5,BG7-BG6,BG8-BG7) -> 0.23 | BH9: =AVERAGE(BH4-BH3,BH5-BH4,BH6-BH5,BH7-BH6,BH8-BH7) -> 0.488 | BI9: =AVERAGE(BI4-BI3,BI5-BI4,BI6-BI5,BI7-BI6,BI8-BI7) -> 0.734 | BJ9: =AVERAGE(BJ4-BJ3,BJ5-BJ4,BJ6-BJ5,BJ7-BJ6,BJ8-BJ7) -> 0.986 | BK9: =AVERAGE(BK4-BK3,BK5-BK4,BK6-BK5,BK7-BK6,BK8-BK7) -> 1.99 | BL9: [g]
A10: MW/min | B10: =B9*0.997 -> 0 | C10: =C9*0.997 -> 0 | D10: =D9*0.997 -> 0 | E10: =E9*0.997 -> 0 | F10: =F9*0.997 -> 0 | G10: =G9*0.997 -> 0 | H10: [ml] | I10: MW/min | J10: =J9*0.997 -> 0.0033233333 | K10: =K9*0.997 -> 0.243268 | L10: =L9*0.997 -> 0.482548 | M10: =M9*0.997 -> 0.71784 | N10: =N9*0.997 -> 0.97706 | O10: =O9*0.997 -> 1.992006 | P10: [ml] | Q10: MW/min | R10: =R9*0.997 -> 0 | S10: =S9*0.997 -> 0.2330986 | T10: =T9*0.997 -> 0.4843426 | U10: =U9*0.997 -> 0.7371818 | V10: =V9*0.997 -> 0.989024 | W10: =W9*0.997 -> 1.507464 | X10: [ml] | Y10: MW/min | Z10: =Z9*0.997 -> 0 | AA10: =AA9*0.997 -> 0.236289 | AB10: =AB9*0.997 -> 0.4913216 | AC10: =AC9*0.997 -> 0.739774 | AD10: =AD9*0.997 -> 0.991018 | AE10: =AE9*0.997 -> 1.980042 | AF10: [ml] | AG10: MW/min | AH10: =AH9*0.997 -> 0 | AI10: =AI9*0.997 -> 0.23928 | AJ10: =AJ9*0.997 -> 0.48853 | AK10: =AK9*0.997 -> 0.741768 | AL10: =AL9*0.997 -> 0.98703 | AM10: =AM9*0.997 -> 1.992006 | AN10: [ml] | AO10: MW/min | AP10: =AP9*0.997 -> 0 | AQ10: =AQ9*0.997 -> 0.241274 | AR10: =AR9*0.997 -> 0.48853 | AS10: =AS9*0.997 -> 0.735786 | AT10: =AT9*0.997 -> 0.983042 | AU10: =AU9*0.997 -> 1.990012 | AV10: [ml] | AW10: MW/min | AX10: =AX9*0.997 -> 0 | AY10: =AY9*0.997 -> 0.241274 | AZ10: =AZ9*0.997 -> 0.491521 | BA10: =BA9*0.997 -> 0.735786 | BB10: =BB9*0.997 -> 0.989024 | BC10: =BC9*0.997 -> 1.980042 | BD10: [ml] | BE10: MW/min | BF10: =BF9*0.997 -> 0 | BG10: =BG9*0.997 -> 0.22931 | BH10: =BH9*0.997 -> 0.486536 | BI10: =BI9*0.997 -> 0.731798 | BJ10: =BJ9*0.997 -> 0.983042 | BK10: =BK9*0.997 -> 1.98403 | BL10: [ml]
I12: #027 | Q12: #028 | Y12: #029 | AG12: #031 | AO12: #032 | AW12: #034 | BE12: #035

Sheet Plateaus
A1: Kanal | B1: Datei | C1: Plateau # | D1: Start [min] | E1: Ende [min] | F1: n Werte | G1: Plateau-MW [µl/min] | H1: Std-Abw. [µl/min] | I1: Min [µl/min] | J1: Max [µl/min] | K1: MW 1. Minute [µl/min] | L1: MW letzte Minute [µl/min] | M1: Drift [%]
A2: Channel 1 | B2: #027 | C2: 1 | D2: 6.88935 | E2: 11.094 | F2: 502 | G2: 229.83281 | H2: 6.975373 | I2: 214.04 | J2: 248.89 | K2: 231.58882 | L2: 231.08433 | M2: =(L2-K2)/G2 -> -0.0021950312
A3: Channel 1 | B3: #027 | C3: 2 | D3: 28.247733 | E3: 32.543183 | F3: 515 | G3: 445.73105 | H3: 14.155344 | I3: 416.61 | J3: 485.7 | K3: 450.72425 | L3: 443.91058 | M3: =(L3-K3)/G3 -> -0.015286498
A4: Channel 1 | B4: #027 | C4: 3 | D4: 34.087683 | E4: 38.42225 | F4: 520 | G4: 645.34042 | H4: 16.984742 | I4: 613.22 | J4: 684.92 | K4: 646.27067 | L4: 641.21258 | M4: =(L4-K4)/G4 -> -0.0078378529
A5: Channel 1 | B5: #027 | C5: 4 | D5: 48.270833 | E5: 52.63625 | F5: 524 | G5: 839.30181 | H5: 19.663426 | I5: 799.99 | J5: 885.29 | K5: 837.53775 | L5: 840.25383 | M5: =(L5-K5)/G5 -> 0.0032361223
A6: Channel 1 | B6: #027 | C6: 5 | D6: 55.027833 | E6: 59.321833 | F6: 515 | G6: 1048.4314 | H6: 109.99603 | I6: 891.91 | J6: 1273.54 | K6: 1206.0508 | L6: 924.39783 | M6: =(L6-K6)/G6 -> -0.2686422
A7: Channel 2 | B7: #028 | C7: 1 | D7: 5.6156833 | E7: 9.8507167 | F7: 506 | G7: 250.29328 | H7: 9.6263345 | I7: 231.28 | J7: 275.11 | K7: 259.8795 | L7: 243.42858 | M7: =(L7-K7)/G7 -> -0.065726545
A8: Channel 2 | B8: #028 | C8: 2 | D8: 11.47335 | E8: 15.78815 | F8: 516 | G8: 494.60833 | H8: 9.4232775 | I8: 481.18 | J8: 519.32 | K8: 494.21942 | L8: 493.76708 | M8: =(L8-K8)/G8 -> -0.00091452833
A9: Channel 2 | B9: #028 | C9: 3 | D9: 17.157917 | E9: 21.4955 | F9: 518 | G9: 756.49376 | H9: 15.800718 | I9: 733.09 | J9: 792.45 | K9: 749.11217 | L9: 763.41633 | M9: =(L9-K9)/G9 -> 0.018908506
A10: Channel 2 | B10: #028 | C10: 4 | D10: 22.89955 | E10: 27.23525 | F10: 519 | G10: 1009.4097 | H10: 18.039691 | I10: 983.74 | J10: 1056.27 | K10: 1005.8751 | L10: 1010.7241 | M10: =(L10-K10)/G10 -> 0.0048037977
A11: Channel 2 | B11: #028 | C11: 5 | D11: 28.697383 | E11: 32.964617 | F11: 511 | G11: 1533.7541 | H11: 34.09607 | I11: 1466.55 | J11: 1631.67 | K11: 1528.6182 | L11: 1525.5563 | M11: =(L11-K11)/G11 -> -0.0019964087
A12: Channel 3 | B12: #029 | C12: 1 | D12: 6.0592 | E12: 10.295917 | F12: 507 | G12: 238.19771 | H12: 24.918815 | I12: 174.61 | J12: 278.8 | K12: 240.13303 | L12: 237.59275 | M12: =(L12-K12)/G12 -> -0.010664566
A13: Channel 3 | B13: #029 | C13: 2 | D13: 12.261583 | E13: 16.51995 | F13: 510 | G13: 467.42224 | H13: 14.51454 | I13: 440.01 | J13: 524.84 | K13: 468.0965 | L13: 467.14775 | M13: =(L13-K13)/G13 -> -0.0020297494
... A36: Channel 7 | B36: #035 | C36: 5 | D36: 29.04735 | E36: 33.33495 | F36: 511 | G36: 2269.3149 | H36: 67.931445 | I36: 2120.67 | J36: 2438.89 | K36: 2318.9548 | L36: 2210.4675 | M36: =(L36-K36)/G36 -> -0.047806196
A38: Methode Plateau-Erkennung (automatisch aus Spalte chX_flow_mean_ulmin):
A39: • Glättung mit gleitendem Median (11 Werte ≈ 5,5 s) nur zur Erkennung, Mittelwerte aus Rohdaten
A40: • Plateau = zusammenhängender Bereich > 100 µl/min mit Dauer ≥ 120 s (kurze Spikes werden ignoriert)
A41: • Einschwingen verworfen: erste 30 s nach Anstieg und letzte 15 s vor Abfall
A42: • Zuordnung Plateau → Flussrate in aufsteigender Reihenfolge (je Datei genau 5 Plateaus gefunden)
A43: • Drift = (MW letzte Minute − MW 1. Minute) / Plateau-MW

Sheet Diagramme
A1: Erkannte Plateaus (orange) mit Plateau-Mittelwert (rot)
